[2024-10-08T21:44:37.177+0000] {local_task_job_runner.py:123} INFO - ::group::Pre task execution logs
[2024-10-08T21:44:37.197+0000] {taskinstance.py:2612} INFO - Dependencies all met for dep_context=non-requeueable deps ti=<TaskInstance: dag_etl_003.run_extract_container_E3 manual__2024-10-08T21:38:05.252967+00:00 [queued]>
[2024-10-08T21:44:37.207+0000] {taskinstance.py:2612} INFO - Dependencies all met for dep_context=requeueable deps ti=<TaskInstance: dag_etl_003.run_extract_container_E3 manual__2024-10-08T21:38:05.252967+00:00 [queued]>
[2024-10-08T21:44:37.208+0000] {taskinstance.py:2865} INFO - Starting attempt 2 of 6
[2024-10-08T21:44:37.250+0000] {taskinstance.py:2888} INFO - Executing <Task(DockerOperator): run_extract_container_E3> on 2024-10-08 21:38:05.252967+00:00
[2024-10-08T21:44:37.260+0000] {warnings.py:112} WARNING - /home/***/.local/lib/python3.12/site-packages/***/task/task_runner/standard_task_runner.py:70: DeprecationWarning: This process (pid=1013) is multi-threaded, use of fork() may lead to deadlocks in the child.
  pid = os.fork()

[2024-10-08T21:44:37.262+0000] {standard_task_runner.py:72} INFO - Started process 1030 to run task
[2024-10-08T21:44:37.262+0000] {standard_task_runner.py:104} INFO - Running: ['***', 'tasks', 'run', 'dag_etl_003', 'run_extract_container_E3', 'manual__2024-10-08T21:38:05.252967+00:00', '--job-id', '94', '--raw', '--subdir', 'DAGS_FOLDER/ETL.py', '--cfg-path', '/tmp/tmp2c6r199u']
[2024-10-08T21:44:37.263+0000] {standard_task_runner.py:105} INFO - Job 94: Subtask run_extract_container_E3
[2024-10-08T21:44:37.328+0000] {task_command.py:467} INFO - Running <TaskInstance: dag_etl_003.run_extract_container_E3 manual__2024-10-08T21:38:05.252967+00:00 [running]> on host a4706156eccf
[2024-10-08T21:44:37.420+0000] {taskinstance.py:3131} INFO - Exporting env vars: AIRFLOW_CTX_DAG_OWNER='BB' AIRFLOW_CTX_DAG_ID='dag_etl_003' AIRFLOW_CTX_TASK_ID='run_extract_container_E3' AIRFLOW_CTX_EXECUTION_DATE='2024-10-08T21:38:05.252967+00:00' AIRFLOW_CTX_TRY_NUMBER='2' AIRFLOW_CTX_DAG_RUN_ID='manual__2024-10-08T21:38:05.252967+00:00'
[2024-10-08T21:44:37.421+0000] {taskinstance.py:731} INFO - ::endgroup::
[2024-10-08T21:44:37.453+0000] {docker.py:367} INFO - Starting docker container from image etl
[2024-10-08T21:44:37.457+0000] {docker.py:375} WARNING - Using remote engine or docker-in-docker and mounting temporary volume from host is not supported. Falling back to `mount_tmp_dir=False` mode. You can set `mount_tmp_dir` parameter to False to disable mounting and remove the warning
[2024-10-08T21:46:18.187+0000] {local_task_job_runner.py:346} WARNING - State of this instance has been externally set to restarting. Terminating instance.
[2024-10-08T21:46:18.188+0000] {local_task_job_runner.py:245} INFO - ::endgroup::
[2024-10-08T21:46:18.191+0000] {process_utils.py:132} INFO - Sending 15 to group 1030. PIDs of all processes in the group: [1030]
[2024-10-08T21:46:18.192+0000] {process_utils.py:87} INFO - Sending the signal 15 to group 1030
[2024-10-08T21:46:18.192+0000] {taskinstance.py:3092} ERROR - Received SIGTERM. Terminating subprocesses.
[2024-10-08T21:46:18.193+0000] {docker.py:533} INFO - Stopping docker container
[2024-10-08T21:46:28.704+0000] {taskinstance.py:3310} ERROR - Task failed with exception
Traceback (most recent call last):
  File "/home/airflow/.local/lib/python3.12/site-packages/docker/api/client.py", line 275, in _raise_for_status
    response.raise_for_status()
  File "/home/airflow/.local/lib/python3.12/site-packages/requests/models.py", line 1024, in raise_for_status
    raise HTTPError(http_error_msg, response=self)
requests.exceptions.HTTPError: 400 Client Error: Bad Request for url: http://docker-socket-proxy:2375/v1.47/containers/create

The above exception was the direct cause of the following exception:

Traceback (most recent call last):
  File "/home/airflow/.local/lib/python3.12/site-packages/airflow/providers/docker/operators/docker.py", line 372, in _run_image
    return self._run_image_with_mounts([*self.mounts, tmp_mount], add_tmp_variable=True)
           ^^^^^^^^^^^^^^^^^^^^^^^^^^^^^^^^^^^^^^^^^^^^^^^^^^^^^^^^^^^^^^^^^^^^^^^^^^^^^
  File "/home/airflow/.local/lib/python3.12/site-packages/airflow/providers/docker/operators/docker.py", line 399, in _run_image_with_mounts
    self.container = self.cli.create_container(
                     ^^^^^^^^^^^^^^^^^^^^^^^^^^
  File "/home/airflow/.local/lib/python3.12/site-packages/docker/api/container.py", line 440, in create_container
    return self.create_container_from_config(config, name, platform)
           ^^^^^^^^^^^^^^^^^^^^^^^^^^^^^^^^^^^^^^^^^^^^^^^^^^^^^^^^^
  File "/home/airflow/.local/lib/python3.12/site-packages/docker/api/container.py", line 457, in create_container_from_config
    return self._result(res, True)
           ^^^^^^^^^^^^^^^^^^^^^^^
  File "/home/airflow/.local/lib/python3.12/site-packages/docker/api/client.py", line 281, in _result
    self._raise_for_status(response)
  File "/home/airflow/.local/lib/python3.12/site-packages/docker/api/client.py", line 277, in _raise_for_status
    raise create_api_error_from_http_exception(e) from e
          ^^^^^^^^^^^^^^^^^^^^^^^^^^^^^^^^^^^^^^^
  File "/home/airflow/.local/lib/python3.12/site-packages/docker/errors.py", line 39, in create_api_error_from_http_exception
    raise cls(e, response=response, explanation=explanation) from e
docker.errors.APIError: 400 Client Error for http://docker-socket-proxy:2375/v1.47/containers/create: Bad Request ("invalid mount config for type "bind": bind source path does not exist: /tmp/airflowtmpqb769o3j")

During handling of the above exception, another exception occurred:

Traceback (most recent call last):
  File "/home/airflow/.local/lib/python3.12/site-packages/airflow/models/taskinstance.py", line 767, in _execute_task
    result = _execute_callable(context=context, **execute_callable_kwargs)
             ^^^^^^^^^^^^^^^^^^^^^^^^^^^^^^^^^^^^^^^^^^^^^^^^^^^^^^^^^^^^^
  File "/home/airflow/.local/lib/python3.12/site-packages/airflow/models/taskinstance.py", line 733, in _execute_callable
    return ExecutionCallableRunner(
           ^^^^^^^^^^^^^^^^^^^^^^^^
  File "/home/airflow/.local/lib/python3.12/site-packages/airflow/utils/operator_helpers.py", line 252, in run
    return self.func(*args, **kwargs)
           ^^^^^^^^^^^^^^^^^^^^^^^^^^
  File "/home/airflow/.local/lib/python3.12/site-packages/airflow/models/baseoperator.py", line 406, in wrapper
    return func(self, *args, **kwargs)
           ^^^^^^^^^^^^^^^^^^^^^^^^^^^
  File "/home/airflow/.local/lib/python3.12/site-packages/airflow/providers/docker/operators/docker.py", line 513, in execute
    return self._run_image()
           ^^^^^^^^^^^^^^^^^
  File "/home/airflow/.local/lib/python3.12/site-packages/airflow/providers/docker/operators/docker.py", line 381, in _run_image
    return self._run_image_with_mounts(self.mounts, add_tmp_variable=False)
           ^^^^^^^^^^^^^^^^^^^^^^^^^^^^^^^^^^^^^^^^^^^^^^^^^^^^^^^^^^^^^^^^
  File "/home/airflow/.local/lib/python3.12/site-packages/airflow/providers/docker/operators/docker.py", line 434, in _run_image_with_mounts
    for log_chunk in logstream:
                     ^^^^^^^^^
  File "/home/airflow/.local/lib/python3.12/site-packages/docker/types/daemon.py", line 29, in __next__
    return next(self._stream)
           ^^^^^^^^^^^^^^^^^^
  File "/home/airflow/.local/lib/python3.12/site-packages/docker/api/client.py", line 438, in <genexpr>
    gen = (data for (_, data) in gen)
                                 ^^^
  File "/home/airflow/.local/lib/python3.12/site-packages/docker/utils/socket.py", line 112, in frames_iter_no_tty
    (stream, n) = next_frame_header(socket)
                  ^^^^^^^^^^^^^^^^^^^^^^^^^
  File "/home/airflow/.local/lib/python3.12/site-packages/docker/utils/socket.py", line 84, in next_frame_header
    data = read_exactly(socket, 8)
           ^^^^^^^^^^^^^^^^^^^^^^^
  File "/home/airflow/.local/lib/python3.12/site-packages/docker/utils/socket.py", line 69, in read_exactly
    next_data = read(socket, n - len(data))
                ^^^^^^^^^^^^^^^^^^^^^^^^^^^
  File "/home/airflow/.local/lib/python3.12/site-packages/docker/utils/socket.py", line 40, in read
    poll.poll()
  File "/home/airflow/.local/lib/python3.12/site-packages/airflow/models/taskinstance.py", line 3094, in signal_handler
    raise AirflowTaskTerminated("Task received SIGTERM signal")
airflow.exceptions.AirflowTaskTerminated: Task received SIGTERM signal
[2024-10-08T21:46:28.710+0000] {taskinstance.py:1225} INFO - Marking task as UP_FOR_RETRY. dag_id=dag_etl_003, task_id=run_extract_container_E3, run_id=manual__2024-10-08T21:38:05.252967+00:00, execution_date=20241008T213805, start_date=20241008T214437, end_date=20241008T214628
[2024-10-08T21:46:28.721+0000] {taskinstance.py:340} INFO - ::group::Post task execution logs
[2024-10-08T21:46:28.759+0000] {process_utils.py:80} INFO - Process psutil.Process(pid=1030, status='terminated', exitcode=2, started='21:44:36') (1030) terminated with exit code 2
