[2024-10-08T21:38:07.776+0000] {local_task_job_runner.py:123} INFO - ::group::Pre task execution logs
[2024-10-08T21:38:07.812+0000] {taskinstance.py:2612} INFO - Dependencies all met for dep_context=non-requeueable deps ti=<TaskInstance: dag_etl_003.run_extract_container_E5 manual__2024-10-08T21:38:05.252967+00:00 [queued]>
[2024-10-08T21:38:07.830+0000] {taskinstance.py:2612} INFO - Dependencies all met for dep_context=requeueable deps ti=<TaskInstance: dag_etl_003.run_extract_container_E5 manual__2024-10-08T21:38:05.252967+00:00 [queued]>
[2024-10-08T21:38:07.831+0000] {taskinstance.py:2865} INFO - Starting attempt 1 of 6
[2024-10-08T21:38:07.856+0000] {taskinstance.py:2888} INFO - Executing <Task(DockerOperator): run_extract_container_E5> on 2024-10-08 21:38:05.252967+00:00
[2024-10-08T21:38:07.878+0000] {warnings.py:112} WARNING - /home/***/.local/lib/python3.12/site-packages/***/task/task_runner/standard_task_runner.py:70: DeprecationWarning: This process (pid=966) is multi-threaded, use of fork() may lead to deadlocks in the child.
  pid = os.fork()

[2024-10-08T21:38:07.885+0000] {standard_task_runner.py:72} INFO - Started process 989 to run task
[2024-10-08T21:38:07.892+0000] {standard_task_runner.py:104} INFO - Running: ['***', 'tasks', 'run', 'dag_etl_003', 'run_extract_container_E5', 'manual__2024-10-08T21:38:05.252967+00:00', '--job-id', '88', '--raw', '--subdir', 'DAGS_FOLDER/ETL.py', '--cfg-path', '/tmp/tmpj5l1aabt']
[2024-10-08T21:38:07.900+0000] {standard_task_runner.py:105} INFO - Job 88: Subtask run_extract_container_E5
[2024-10-08T21:38:08.004+0000] {task_command.py:467} INFO - Running <TaskInstance: dag_etl_003.run_extract_container_E5 manual__2024-10-08T21:38:05.252967+00:00 [running]> on host a4706156eccf
[2024-10-08T21:38:08.165+0000] {taskinstance.py:3131} INFO - Exporting env vars: AIRFLOW_CTX_DAG_OWNER='BB' AIRFLOW_CTX_DAG_ID='dag_etl_003' AIRFLOW_CTX_TASK_ID='run_extract_container_E5' AIRFLOW_CTX_EXECUTION_DATE='2024-10-08T21:38:05.252967+00:00' AIRFLOW_CTX_TRY_NUMBER='1' AIRFLOW_CTX_DAG_RUN_ID='manual__2024-10-08T21:38:05.252967+00:00'
[2024-10-08T21:38:08.166+0000] {taskinstance.py:731} INFO - ::endgroup::
[2024-10-08T21:38:08.255+0000] {docker.py:367} INFO - Starting docker container from image etl
[2024-10-08T21:38:08.261+0000] {docker.py:375} WARNING - Using remote engine or docker-in-docker and mounting temporary volume from host is not supported. Falling back to `mount_tmp_dir=False` mode. You can set `mount_tmp_dir` parameter to False to disable mounting and remove the warning
[2024-10-08T21:38:40.373+0000] {job.py:229} INFO - Heartbeat recovered after 18.05 seconds
[2024-10-08T21:39:31.215+0000] {docker.py:438} INFO - Traceback (most recent call last):
[2024-10-08T21:39:31.245+0000] {docker.py:438} INFO -   File "/app/extract.py", line 37, in <module>
[2024-10-08T21:39:31.246+0000] {docker.py:438} INFO -     driver = webdriver.Chrome(service=Service(ChromeDriverManager().install()),options=options)
[2024-10-08T21:39:31.247+0000] {docker.py:438} INFO -   File "/usr/local/lib/python3.10/site-packages/selenium/webdriver/chrome/webdriver.py", line 84, in __init__
[2024-10-08T21:39:31.247+0000] {docker.py:438} INFO -     super().__init__(
[2024-10-08T21:39:31.247+0000] {docker.py:438} INFO -   File "/usr/local/lib/python3.10/site-packages/selenium/webdriver/chromium/webdriver.py", line 104, in __init__
[2024-10-08T21:39:31.267+0000] {docker.py:438} INFO -     super().__init__(
[2024-10-08T21:39:31.281+0000] {docker.py:438} INFO -   File "/usr/local/lib/python3.10/site-packages/selenium/webdriver/remote/webdriver.py", line 286, in __init__
[2024-10-08T21:39:31.285+0000] {docker.py:438} INFO -     self.start_session(capabilities, browser_profile)
[2024-10-08T21:39:31.292+0000] {docker.py:438} INFO -   File "/usr/local/lib/python3.10/site-packages/selenium/webdriver/remote/webdriver.py", line 378, in start_session
[2024-10-08T21:39:31.293+0000] {docker.py:438} INFO -     response = self.execute(Command.NEW_SESSION, parameters)
[2024-10-08T21:39:31.293+0000] {docker.py:438} INFO -   File "/usr/local/lib/python3.10/site-packages/selenium/webdriver/remote/webdriver.py", line 440, in execute
[2024-10-08T21:39:31.299+0000] {docker.py:438} INFO -     self.error_handler.check_response(response)
[2024-10-08T21:39:31.300+0000] {docker.py:438} INFO -   File "/usr/local/lib/python3.10/site-packages/selenium/webdriver/remote/errorhandler.py", line 245, in check_response
[2024-10-08T21:39:31.320+0000] {docker.py:438} INFO -     raise exception_class(message, screen, stacktrace)
[2024-10-08T21:39:31.321+0000] {docker.py:438} INFO - selenium.common.exceptions.SessionNotCreatedException: Message: session not created: DevToolsActivePort file doesn't exist
[2024-10-08T21:39:31.321+0000] {docker.py:438} INFO - Stacktrace:
[2024-10-08T21:39:31.326+0000] {docker.py:438} INFO - #0 0x55c151ff5f8a <unknown>
[2024-10-08T21:39:31.334+0000] {docker.py:438} INFO - #1 0x55c151cdc5e0 <unknown>
[2024-10-08T21:39:31.334+0000] {docker.py:438} INFO - #2 0x55c151d198b9 <unknown>
[2024-10-08T21:39:31.335+0000] {docker.py:438} INFO - #3 0x55c151d15123 <unknown>
[2024-10-08T21:39:31.360+0000] {docker.py:438} INFO - #4 0x55c151d102c5 <unknown>
[2024-10-08T21:39:31.361+0000] {docker.py:438} INFO - #5 0x55c151d5cdf6 <unknown>
[2024-10-08T21:39:31.361+0000] {docker.py:438} INFO - #6 0x55c151d5c446 <unknown>
[2024-10-08T21:39:31.376+0000] {docker.py:438} INFO - #7 0x55c151d508c3 <unknown>
[2024-10-08T21:39:31.379+0000] {docker.py:438} INFO - #8 0x55c151d1e6b3 <unknown>
[2024-10-08T21:39:31.387+0000] {docker.py:438} INFO - #9 0x55c151d1f68e <unknown>
[2024-10-08T21:39:31.419+0000] {docker.py:438} INFO - #10 0x55c151fc098b <unknown>
[2024-10-08T21:39:31.424+0000] {docker.py:438} INFO - #11 0x55c151fc4911 <unknown>
[2024-10-08T21:39:31.428+0000] {docker.py:438} INFO - #12 0x55c151fad185 <unknown>
[2024-10-08T21:39:31.428+0000] {docker.py:438} INFO - #13 0x55c151fc5492 <unknown>
[2024-10-08T21:39:31.429+0000] {docker.py:438} INFO - #14 0x55c151f922ef <unknown>
[2024-10-08T21:39:31.429+0000] {docker.py:438} INFO - #15 0x55c151fe4e88 <unknown>
[2024-10-08T21:39:31.429+0000] {docker.py:438} INFO - #16 0x55c151fe5053 <unknown>
[2024-10-08T21:39:31.430+0000] {docker.py:438} INFO - #17 0x55c151ff4ddc <unknown>
[2024-10-08T21:39:31.436+0000] {docker.py:438} INFO - #18 0x7f3a031e9144 <unknown>
[2024-10-08T21:39:31.859+0000] {job.py:229} INFO - Heartbeat recovered after 53.19 seconds
[2024-10-08T21:39:35.631+0000] {taskinstance.py:3310} ERROR - Task failed with exception
Traceback (most recent call last):
  File "/home/airflow/.local/lib/python3.12/site-packages/docker/api/client.py", line 275, in _raise_for_status
    response.raise_for_status()
  File "/home/airflow/.local/lib/python3.12/site-packages/requests/models.py", line 1024, in raise_for_status
    raise HTTPError(http_error_msg, response=self)
requests.exceptions.HTTPError: 400 Client Error: Bad Request for url: http://docker-socket-proxy:2375/v1.47/containers/create

The above exception was the direct cause of the following exception:

Traceback (most recent call last):
  File "/home/airflow/.local/lib/python3.12/site-packages/airflow/providers/docker/operators/docker.py", line 372, in _run_image
    return self._run_image_with_mounts([*self.mounts, tmp_mount], add_tmp_variable=True)
           ^^^^^^^^^^^^^^^^^^^^^^^^^^^^^^^^^^^^^^^^^^^^^^^^^^^^^^^^^^^^^^^^^^^^^^^^^^^^^
  File "/home/airflow/.local/lib/python3.12/site-packages/airflow/providers/docker/operators/docker.py", line 399, in _run_image_with_mounts
    self.container = self.cli.create_container(
                     ^^^^^^^^^^^^^^^^^^^^^^^^^^
  File "/home/airflow/.local/lib/python3.12/site-packages/docker/api/container.py", line 440, in create_container
    return self.create_container_from_config(config, name, platform)
           ^^^^^^^^^^^^^^^^^^^^^^^^^^^^^^^^^^^^^^^^^^^^^^^^^^^^^^^^^
  File "/home/airflow/.local/lib/python3.12/site-packages/docker/api/container.py", line 457, in create_container_from_config
    return self._result(res, True)
           ^^^^^^^^^^^^^^^^^^^^^^^
  File "/home/airflow/.local/lib/python3.12/site-packages/docker/api/client.py", line 281, in _result
    self._raise_for_status(response)
  File "/home/airflow/.local/lib/python3.12/site-packages/docker/api/client.py", line 277, in _raise_for_status
    raise create_api_error_from_http_exception(e) from e
          ^^^^^^^^^^^^^^^^^^^^^^^^^^^^^^^^^^^^^^^
  File "/home/airflow/.local/lib/python3.12/site-packages/docker/errors.py", line 39, in create_api_error_from_http_exception
    raise cls(e, response=response, explanation=explanation) from e
docker.errors.APIError: 400 Client Error for http://docker-socket-proxy:2375/v1.47/containers/create: Bad Request ("invalid mount config for type "bind": bind source path does not exist: /tmp/airflowtmpd_pvu8wj")

During handling of the above exception, another exception occurred:

Traceback (most recent call last):
  File "/home/airflow/.local/lib/python3.12/site-packages/airflow/models/taskinstance.py", line 767, in _execute_task
    result = _execute_callable(context=context, **execute_callable_kwargs)
             ^^^^^^^^^^^^^^^^^^^^^^^^^^^^^^^^^^^^^^^^^^^^^^^^^^^^^^^^^^^^^
  File "/home/airflow/.local/lib/python3.12/site-packages/airflow/models/taskinstance.py", line 733, in _execute_callable
    return ExecutionCallableRunner(
           ^^^^^^^^^^^^^^^^^^^^^^^^
  File "/home/airflow/.local/lib/python3.12/site-packages/airflow/utils/operator_helpers.py", line 252, in run
    return self.func(*args, **kwargs)
           ^^^^^^^^^^^^^^^^^^^^^^^^^^
  File "/home/airflow/.local/lib/python3.12/site-packages/airflow/models/baseoperator.py", line 406, in wrapper
    return func(self, *args, **kwargs)
           ^^^^^^^^^^^^^^^^^^^^^^^^^^^
  File "/home/airflow/.local/lib/python3.12/site-packages/airflow/providers/docker/operators/docker.py", line 513, in execute
    return self._run_image()
           ^^^^^^^^^^^^^^^^^
  File "/home/airflow/.local/lib/python3.12/site-packages/airflow/providers/docker/operators/docker.py", line 381, in _run_image
    return self._run_image_with_mounts(self.mounts, add_tmp_variable=False)
           ^^^^^^^^^^^^^^^^^^^^^^^^^^^^^^^^^^^^^^^^^^^^^^^^^^^^^^^^^^^^^^^^
  File "/home/airflow/.local/lib/python3.12/site-packages/airflow/providers/docker/operators/docker.py", line 446, in _run_image_with_mounts
    raise DockerContainerFailedException(f"Docker container failed: {result!r}", logs=log_lines)
airflow.providers.docker.exceptions.DockerContainerFailedException: Docker container failed: {'StatusCode': 1}
[2024-10-08T21:39:35.686+0000] {taskinstance.py:1225} INFO - Marking task as UP_FOR_RETRY. dag_id=dag_etl_003, task_id=run_extract_container_E5, run_id=manual__2024-10-08T21:38:05.252967+00:00, execution_date=20241008T213805, start_date=20241008T213807, end_date=20241008T213935
[2024-10-08T21:39:35.814+0000] {taskinstance.py:340} INFO - ::group::Post task execution logs
[2024-10-08T21:39:35.815+0000] {standard_task_runner.py:124} ERROR - Failed to execute job 88 for task run_extract_container_E5 (Docker container failed: {'StatusCode': 1}; 989)
Traceback (most recent call last):
  File "/home/airflow/.local/lib/python3.12/site-packages/docker/api/client.py", line 275, in _raise_for_status
    response.raise_for_status()
  File "/home/airflow/.local/lib/python3.12/site-packages/requests/models.py", line 1024, in raise_for_status
    raise HTTPError(http_error_msg, response=self)
requests.exceptions.HTTPError: 400 Client Error: Bad Request for url: http://docker-socket-proxy:2375/v1.47/containers/create

The above exception was the direct cause of the following exception:

Traceback (most recent call last):
  File "/home/airflow/.local/lib/python3.12/site-packages/airflow/providers/docker/operators/docker.py", line 372, in _run_image
    return self._run_image_with_mounts([*self.mounts, tmp_mount], add_tmp_variable=True)
           ^^^^^^^^^^^^^^^^^^^^^^^^^^^^^^^^^^^^^^^^^^^^^^^^^^^^^^^^^^^^^^^^^^^^^^^^^^^^^
  File "/home/airflow/.local/lib/python3.12/site-packages/airflow/providers/docker/operators/docker.py", line 399, in _run_image_with_mounts
    self.container = self.cli.create_container(
                     ^^^^^^^^^^^^^^^^^^^^^^^^^^
  File "/home/airflow/.local/lib/python3.12/site-packages/docker/api/container.py", line 440, in create_container
    return self.create_container_from_config(config, name, platform)
           ^^^^^^^^^^^^^^^^^^^^^^^^^^^^^^^^^^^^^^^^^^^^^^^^^^^^^^^^^
  File "/home/airflow/.local/lib/python3.12/site-packages/docker/api/container.py", line 457, in create_container_from_config
    return self._result(res, True)
           ^^^^^^^^^^^^^^^^^^^^^^^
  File "/home/airflow/.local/lib/python3.12/site-packages/docker/api/client.py", line 281, in _result
    self._raise_for_status(response)
  File "/home/airflow/.local/lib/python3.12/site-packages/docker/api/client.py", line 277, in _raise_for_status
    raise create_api_error_from_http_exception(e) from e
          ^^^^^^^^^^^^^^^^^^^^^^^^^^^^^^^^^^^^^^^
  File "/home/airflow/.local/lib/python3.12/site-packages/docker/errors.py", line 39, in create_api_error_from_http_exception
    raise cls(e, response=response, explanation=explanation) from e
docker.errors.APIError: 400 Client Error for http://docker-socket-proxy:2375/v1.47/containers/create: Bad Request ("invalid mount config for type "bind": bind source path does not exist: /tmp/airflowtmpd_pvu8wj")

During handling of the above exception, another exception occurred:

Traceback (most recent call last):
  File "/home/airflow/.local/lib/python3.12/site-packages/airflow/task/task_runner/standard_task_runner.py", line 117, in _start_by_fork
    ret = args.func(args, dag=self.dag)
          ^^^^^^^^^^^^^^^^^^^^^^^^^^^^^
  File "/home/airflow/.local/lib/python3.12/site-packages/airflow/cli/cli_config.py", line 49, in command
    return func(*args, **kwargs)
           ^^^^^^^^^^^^^^^^^^^^^
  File "/home/airflow/.local/lib/python3.12/site-packages/airflow/utils/cli.py", line 115, in wrapper
    return f(*args, **kwargs)
           ^^^^^^^^^^^^^^^^^^
  File "/home/airflow/.local/lib/python3.12/site-packages/airflow/cli/commands/task_command.py", line 483, in task_run
    task_return_code = _run_task_by_selected_method(args, _dag, ti)
                       ^^^^^^^^^^^^^^^^^^^^^^^^^^^^^^^^^^^^^^^^^^^^
  File "/home/airflow/.local/lib/python3.12/site-packages/airflow/cli/commands/task_command.py", line 256, in _run_task_by_selected_method
    return _run_raw_task(args, ti)
           ^^^^^^^^^^^^^^^^^^^^^^^
  File "/home/airflow/.local/lib/python3.12/site-packages/airflow/cli/commands/task_command.py", line 341, in _run_raw_task
    return ti._run_raw_task(
           ^^^^^^^^^^^^^^^^^
  File "/home/airflow/.local/lib/python3.12/site-packages/airflow/utils/session.py", line 97, in wrapper
    return func(*args, session=session, **kwargs)
           ^^^^^^^^^^^^^^^^^^^^^^^^^^^^^^^^^^^^^^
  File "/home/airflow/.local/lib/python3.12/site-packages/airflow/models/taskinstance.py", line 3004, in _run_raw_task
    return _run_raw_task(
           ^^^^^^^^^^^^^^
  File "/home/airflow/.local/lib/python3.12/site-packages/airflow/models/taskinstance.py", line 273, in _run_raw_task
    TaskInstance._execute_task_with_callbacks(
  File "/home/airflow/.local/lib/python3.12/site-packages/airflow/models/taskinstance.py", line 3158, in _execute_task_with_callbacks
    result = self._execute_task(context, task_orig)
             ^^^^^^^^^^^^^^^^^^^^^^^^^^^^^^^^^^^^^^
  File "/home/airflow/.local/lib/python3.12/site-packages/airflow/models/taskinstance.py", line 3182, in _execute_task
    return _execute_task(self, context, task_orig)
           ^^^^^^^^^^^^^^^^^^^^^^^^^^^^^^^^^^^^^^^
  File "/home/airflow/.local/lib/python3.12/site-packages/airflow/models/taskinstance.py", line 767, in _execute_task
    result = _execute_callable(context=context, **execute_callable_kwargs)
             ^^^^^^^^^^^^^^^^^^^^^^^^^^^^^^^^^^^^^^^^^^^^^^^^^^^^^^^^^^^^^
  File "/home/airflow/.local/lib/python3.12/site-packages/airflow/models/taskinstance.py", line 733, in _execute_callable
    return ExecutionCallableRunner(
           ^^^^^^^^^^^^^^^^^^^^^^^^
  File "/home/airflow/.local/lib/python3.12/site-packages/airflow/utils/operator_helpers.py", line 252, in run
    return self.func(*args, **kwargs)
           ^^^^^^^^^^^^^^^^^^^^^^^^^^
  File "/home/airflow/.local/lib/python3.12/site-packages/airflow/models/baseoperator.py", line 406, in wrapper
    return func(self, *args, **kwargs)
           ^^^^^^^^^^^^^^^^^^^^^^^^^^^
  File "/home/airflow/.local/lib/python3.12/site-packages/airflow/providers/docker/operators/docker.py", line 513, in execute
    return self._run_image()
           ^^^^^^^^^^^^^^^^^
  File "/home/airflow/.local/lib/python3.12/site-packages/airflow/providers/docker/operators/docker.py", line 381, in _run_image
    return self._run_image_with_mounts(self.mounts, add_tmp_variable=False)
           ^^^^^^^^^^^^^^^^^^^^^^^^^^^^^^^^^^^^^^^^^^^^^^^^^^^^^^^^^^^^^^^^
  File "/home/airflow/.local/lib/python3.12/site-packages/airflow/providers/docker/operators/docker.py", line 446, in _run_image_with_mounts
    raise DockerContainerFailedException(f"Docker container failed: {result!r}", logs=log_lines)
airflow.providers.docker.exceptions.DockerContainerFailedException: Docker container failed: {'StatusCode': 1}
[2024-10-08T21:39:35.874+0000] {local_task_job_runner.py:266} INFO - Task exited with return code 1
[2024-10-08T21:39:35.890+0000] {local_task_job_runner.py:245} INFO - ::endgroup::
